2024-12-03 10:50:41,381 - app - ERROR - Internal Server Error: 500 Internal Server Error: The server encountered an internal error and was unable to complete your request. Either the server is overloaded or there is an error in the application.
2024-12-03 10:54:37,540 - app - ERROR - Exception on /chat [POST]
Traceback (most recent call last):
  File "/home/user/Desktop/uvlhub_practicas/venv/lib/python3.12/site-packages/flask/app.py", line 1473, in wsgi_app
    response = self.full_dispatch_request()
               ^^^^^^^^^^^^^^^^^^^^^^^^^^^^
  File "/home/user/Desktop/uvlhub_practicas/venv/lib/python3.12/site-packages/flask/app.py", line 882, in full_dispatch_request
    rv = self.handle_user_exception(e)
         ^^^^^^^^^^^^^^^^^^^^^^^^^^^^^
  File "/home/user/Desktop/uvlhub_practicas/venv/lib/python3.12/site-packages/flask_restful/__init__.py", line 298, in error_router
    return original_handler(e)
           ^^^^^^^^^^^^^^^^^^^
  File "/home/user/Desktop/uvlhub_practicas/venv/lib/python3.12/site-packages/flask/app.py", line 880, in full_dispatch_request
    rv = self.dispatch_request()
         ^^^^^^^^^^^^^^^^^^^^^^^
  File "/home/user/Desktop/uvlhub_practicas/venv/lib/python3.12/site-packages/flask/app.py", line 865, in dispatch_request
    return self.ensure_sync(self.view_functions[rule.endpoint])(**view_args)  # type: ignore[no-any-return]
           ^^^^^^^^^^^^^^^^^^^^^^^^^^^^^^^^^^^^^^^^^^^^^^^^^^^^^^^^^^^^^^^^^
  File "/home/user/Desktop/uvlhub_practicas/montaito-hub/app/modules/ai/routes.py", line 105, in chat
    feature_model = format_feature_model_response(feature_model)
                    ^^^^^^^^^^^^^^^^^^^^^^^^^^^^^^^^^^^^^^^^^^^^
  File "/home/user/Desktop/uvlhub_practicas/montaito-hub/app/modules/ai/routes.py", line 39, in format_feature_model_response
    authors = "\n".join([f"  - {author['name']} ({author['affiliation']})" for author in feature_model['authors']])
                                                                                         ~~~~~~~~~~~~~^^^^^^^^^^^
TypeError: 'FMMetaData' object is not subscriptable
2024-12-03 10:54:37,542 - app - ERROR - Internal Server Error: 500 Internal Server Error: The server encountered an internal error and was unable to complete your request. Either the server is overloaded or there is an error in the application.
2024-12-03 11:20:46,521 - app - ERROR - Exception on /chat [POST]
Traceback (most recent call last):
  File "/home/user/Desktop/uvlhub_practicas/venv/lib/python3.12/site-packages/flask/app.py", line 1473, in wsgi_app
    response = self.full_dispatch_request()
               ^^^^^^^^^^^^^^^^^^^^^^^^^^^^
  File "/home/user/Desktop/uvlhub_practicas/venv/lib/python3.12/site-packages/flask/app.py", line 882, in full_dispatch_request
    rv = self.handle_user_exception(e)
         ^^^^^^^^^^^^^^^^^^^^^^^^^^^^^
  File "/home/user/Desktop/uvlhub_practicas/venv/lib/python3.12/site-packages/flask_restful/__init__.py", line 298, in error_router
    return original_handler(e)
           ^^^^^^^^^^^^^^^^^^^
  File "/home/user/Desktop/uvlhub_practicas/venv/lib/python3.12/site-packages/flask/app.py", line 880, in full_dispatch_request
    rv = self.dispatch_request()
         ^^^^^^^^^^^^^^^^^^^^^^^
  File "/home/user/Desktop/uvlhub_practicas/venv/lib/python3.12/site-packages/flask/app.py", line 865, in dispatch_request
    return self.ensure_sync(self.view_functions[rule.endpoint])(**view_args)  # type: ignore[no-any-return]
           ^^^^^^^^^^^^^^^^^^^^^^^^^^^^^^^^^^^^^^^^^^^^^^^^^^^^^^^^^^^^^^^^^
  File "/home/user/Desktop/uvlhub_practicas/montaito-hub/app/modules/ai/routes.py", line 89, in chat
    return jsonify({"response": response_text})
           ^^^^^^^^^^^^^^^^^^^^^^^^^^^^^^^^^^^^
  File "/home/user/Desktop/uvlhub_practicas/venv/lib/python3.12/site-packages/flask/json/__init__.py", line 170, in jsonify
    return current_app.json.response(*args, **kwargs)  # type: ignore[return-value]
           ^^^^^^^^^^^^^^^^^^^^^^^^^^^^^^^^^^^^^^^^^^
  File "/home/user/Desktop/uvlhub_practicas/venv/lib/python3.12/site-packages/flask/json/provider.py", line 214, in response
    f"{self.dumps(obj, **dump_args)}\n", mimetype=self.mimetype
       ^^^^^^^^^^^^^^^^^^^^^^^^^^^^
  File "/home/user/Desktop/uvlhub_practicas/venv/lib/python3.12/site-packages/flask/json/provider.py", line 179, in dumps
    return json.dumps(obj, **kwargs)
           ^^^^^^^^^^^^^^^^^^^^^^^^^
  File "/usr/lib/python3.12/json/__init__.py", line 238, in dumps
    **kw).encode(obj)
          ^^^^^^^^^^^
  File "/usr/lib/python3.12/json/encoder.py", line 200, in encode
    chunks = self.iterencode(o, _one_shot=True)
             ^^^^^^^^^^^^^^^^^^^^^^^^^^^^^^^^^^
  File "/usr/lib/python3.12/json/encoder.py", line 258, in iterencode
    return _iterencode(o, 0)
           ^^^^^^^^^^^^^^^^^
  File "/home/user/Desktop/uvlhub_practicas/venv/lib/python3.12/site-packages/flask/json/provider.py", line 121, in _default
    raise TypeError(f"Object of type {type(o).__name__} is not JSON serializable")
TypeError: Object of type FMMetaData is not JSON serializable
2024-12-03 11:20:46,547 - app - ERROR - Internal Server Error: 500 Internal Server Error: The server encountered an internal error and was unable to complete your request. Either the server is overloaded or there is an error in the application.
2024-12-03 11:21:17,865 - app - ERROR - Exception on /chat [POST]
Traceback (most recent call last):
  File "/home/user/Desktop/uvlhub_practicas/venv/lib/python3.12/site-packages/flask/app.py", line 1473, in wsgi_app
    response = self.full_dispatch_request()
               ^^^^^^^^^^^^^^^^^^^^^^^^^^^^
  File "/home/user/Desktop/uvlhub_practicas/venv/lib/python3.12/site-packages/flask/app.py", line 882, in full_dispatch_request
    rv = self.handle_user_exception(e)
         ^^^^^^^^^^^^^^^^^^^^^^^^^^^^^
  File "/home/user/Desktop/uvlhub_practicas/venv/lib/python3.12/site-packages/flask_restful/__init__.py", line 298, in error_router
    return original_handler(e)
           ^^^^^^^^^^^^^^^^^^^
  File "/home/user/Desktop/uvlhub_practicas/venv/lib/python3.12/site-packages/flask/app.py", line 880, in full_dispatch_request
    rv = self.dispatch_request()
         ^^^^^^^^^^^^^^^^^^^^^^^
  File "/home/user/Desktop/uvlhub_practicas/venv/lib/python3.12/site-packages/flask/app.py", line 865, in dispatch_request
    return self.ensure_sync(self.view_functions[rule.endpoint])(**view_args)  # type: ignore[no-any-return]
           ^^^^^^^^^^^^^^^^^^^^^^^^^^^^^^^^^^^^^^^^^^^^^^^^^^^^^^^^^^^^^^^^^
  File "/home/user/Desktop/uvlhub_practicas/montaito-hub/app/modules/ai/routes.py", line 89, in chat
    return jsonify({"response": response_text})
           ^^^^^^^^^^^^^^^^^^^^^^^^^^^^^^^^^^^^
  File "/home/user/Desktop/uvlhub_practicas/venv/lib/python3.12/site-packages/flask/json/__init__.py", line 170, in jsonify
    return current_app.json.response(*args, **kwargs)  # type: ignore[return-value]
           ^^^^^^^^^^^^^^^^^^^^^^^^^^^^^^^^^^^^^^^^^^
  File "/home/user/Desktop/uvlhub_practicas/venv/lib/python3.12/site-packages/flask/json/provider.py", line 214, in response
    f"{self.dumps(obj, **dump_args)}\n", mimetype=self.mimetype
       ^^^^^^^^^^^^^^^^^^^^^^^^^^^^
  File "/home/user/Desktop/uvlhub_practicas/venv/lib/python3.12/site-packages/flask/json/provider.py", line 179, in dumps
    return json.dumps(obj, **kwargs)
           ^^^^^^^^^^^^^^^^^^^^^^^^^
  File "/usr/lib/python3.12/json/__init__.py", line 238, in dumps
    **kw).encode(obj)
          ^^^^^^^^^^^
  File "/usr/lib/python3.12/json/encoder.py", line 200, in encode
    chunks = self.iterencode(o, _one_shot=True)
             ^^^^^^^^^^^^^^^^^^^^^^^^^^^^^^^^^^
  File "/usr/lib/python3.12/json/encoder.py", line 258, in iterencode
    return _iterencode(o, 0)
           ^^^^^^^^^^^^^^^^^
  File "/home/user/Desktop/uvlhub_practicas/venv/lib/python3.12/site-packages/flask/json/provider.py", line 121, in _default
    raise TypeError(f"Object of type {type(o).__name__} is not JSON serializable")
TypeError: Object of type FeatureModel is not JSON serializable
2024-12-03 11:21:17,869 - app - ERROR - Internal Server Error: 500 Internal Server Error: The server encountered an internal error and was unable to complete your request. Either the server is overloaded or there is an error in the application.
