2024-12-10 17:15:49,736 - app - ERROR - Exception on /chat [POST]
Traceback (most recent call last):
  File "/home/user/Desktop/uvlhub_practicas/venv/lib/python3.12/site-packages/flask/app.py", line 1473, in wsgi_app
    response = self.full_dispatch_request()
               ^^^^^^^^^^^^^^^^^^^^^^^^^^^^
  File "/home/user/Desktop/uvlhub_practicas/venv/lib/python3.12/site-packages/flask/app.py", line 882, in full_dispatch_request
    rv = self.handle_user_exception(e)
         ^^^^^^^^^^^^^^^^^^^^^^^^^^^^^
  File "/home/user/Desktop/uvlhub_practicas/venv/lib/python3.12/site-packages/flask_restful/__init__.py", line 298, in error_router
    return original_handler(e)
           ^^^^^^^^^^^^^^^^^^^
  File "/home/user/Desktop/uvlhub_practicas/venv/lib/python3.12/site-packages/flask/app.py", line 880, in full_dispatch_request
    rv = self.dispatch_request()
         ^^^^^^^^^^^^^^^^^^^^^^^
  File "/home/user/Desktop/uvlhub_practicas/venv/lib/python3.12/site-packages/flask/app.py", line 865, in dispatch_request
    return self.ensure_sync(self.view_functions[rule.endpoint])(**view_args)  # type: ignore[no-any-return]
           ^^^^^^^^^^^^^^^^^^^^^^^^^^^^^^^^^^^^^^^^^^^^^^^^^^^^^^^^^^^^^^^^^
  File "/home/user/Desktop/uvlhub_practicas/montaito-hub/app/modules/ai/routes.py", line 70, in chat
    if response_text.startswith('dataset-get'):
       ^^^^^^^^^^^^^^^^^^^^^^^^
AttributeError: 'dict' object has no attribute 'startswith'
2024-12-10 17:15:49,740 - app - ERROR - Internal Server Error: 500 Internal Server Error: The server encountered an internal error and was unable to complete your request. Either the server is overloaded or there is an error in the application.
2024-12-10 17:15:54,785 - app - ERROR - Exception on /chat [POST]
Traceback (most recent call last):
  File "/home/user/Desktop/uvlhub_practicas/venv/lib/python3.12/site-packages/flask/app.py", line 1473, in wsgi_app
    response = self.full_dispatch_request()
               ^^^^^^^^^^^^^^^^^^^^^^^^^^^^
  File "/home/user/Desktop/uvlhub_practicas/venv/lib/python3.12/site-packages/flask/app.py", line 882, in full_dispatch_request
    rv = self.handle_user_exception(e)
         ^^^^^^^^^^^^^^^^^^^^^^^^^^^^^
  File "/home/user/Desktop/uvlhub_practicas/venv/lib/python3.12/site-packages/flask_restful/__init__.py", line 298, in error_router
    return original_handler(e)
           ^^^^^^^^^^^^^^^^^^^
  File "/home/user/Desktop/uvlhub_practicas/venv/lib/python3.12/site-packages/flask/app.py", line 880, in full_dispatch_request
    rv = self.dispatch_request()
         ^^^^^^^^^^^^^^^^^^^^^^^
  File "/home/user/Desktop/uvlhub_practicas/venv/lib/python3.12/site-packages/flask/app.py", line 865, in dispatch_request
    return self.ensure_sync(self.view_functions[rule.endpoint])(**view_args)  # type: ignore[no-any-return]
           ^^^^^^^^^^^^^^^^^^^^^^^^^^^^^^^^^^^^^^^^^^^^^^^^^^^^^^^^^^^^^^^^^
  File "/home/user/Desktop/uvlhub_practicas/montaito-hub/app/modules/ai/routes.py", line 70, in chat
    if response_text.startswith('dataset-get'):
       ^^^^^^^^^^^^^^^^^^^^^^^^
AttributeError: 'dict' object has no attribute 'startswith'
2024-12-10 17:15:54,791 - app - ERROR - Internal Server Error: 500 Internal Server Error: The server encountered an internal error and was unable to complete your request. Either the server is overloaded or there is an error in the application.
2024-12-10 17:15:57,214 - app - ERROR - Exception on /chat [POST]
Traceback (most recent call last):
  File "/home/user/Desktop/uvlhub_practicas/venv/lib/python3.12/site-packages/flask/app.py", line 1473, in wsgi_app
    response = self.full_dispatch_request()
               ^^^^^^^^^^^^^^^^^^^^^^^^^^^^
  File "/home/user/Desktop/uvlhub_practicas/venv/lib/python3.12/site-packages/flask/app.py", line 882, in full_dispatch_request
    rv = self.handle_user_exception(e)
         ^^^^^^^^^^^^^^^^^^^^^^^^^^^^^
  File "/home/user/Desktop/uvlhub_practicas/venv/lib/python3.12/site-packages/flask_restful/__init__.py", line 298, in error_router
    return original_handler(e)
           ^^^^^^^^^^^^^^^^^^^
  File "/home/user/Desktop/uvlhub_practicas/venv/lib/python3.12/site-packages/flask/app.py", line 880, in full_dispatch_request
    rv = self.dispatch_request()
         ^^^^^^^^^^^^^^^^^^^^^^^
  File "/home/user/Desktop/uvlhub_practicas/venv/lib/python3.12/site-packages/flask/app.py", line 865, in dispatch_request
    return self.ensure_sync(self.view_functions[rule.endpoint])(**view_args)  # type: ignore[no-any-return]
           ^^^^^^^^^^^^^^^^^^^^^^^^^^^^^^^^^^^^^^^^^^^^^^^^^^^^^^^^^^^^^^^^^
  File "/home/user/Desktop/uvlhub_practicas/montaito-hub/app/modules/ai/routes.py", line 70, in chat
    if response_text.startswith('dataset-get'):
       ^^^^^^^^^^^^^^^^^^^^^^^^
AttributeError: 'dict' object has no attribute 'startswith'
2024-12-10 17:15:57,215 - app - ERROR - Internal Server Error: 500 Internal Server Error: The server encountered an internal error and was unable to complete your request. Either the server is overloaded or there is an error in the application.
2024-12-10 17:15:59,061 - app - ERROR - Exception on /chat [POST]
Traceback (most recent call last):
  File "/home/user/Desktop/uvlhub_practicas/venv/lib/python3.12/site-packages/flask/app.py", line 1473, in wsgi_app
    response = self.full_dispatch_request()
               ^^^^^^^^^^^^^^^^^^^^^^^^^^^^
  File "/home/user/Desktop/uvlhub_practicas/venv/lib/python3.12/site-packages/flask/app.py", line 882, in full_dispatch_request
    rv = self.handle_user_exception(e)
         ^^^^^^^^^^^^^^^^^^^^^^^^^^^^^
  File "/home/user/Desktop/uvlhub_practicas/venv/lib/python3.12/site-packages/flask_restful/__init__.py", line 298, in error_router
    return original_handler(e)
           ^^^^^^^^^^^^^^^^^^^
  File "/home/user/Desktop/uvlhub_practicas/venv/lib/python3.12/site-packages/flask/app.py", line 880, in full_dispatch_request
    rv = self.dispatch_request()
         ^^^^^^^^^^^^^^^^^^^^^^^
  File "/home/user/Desktop/uvlhub_practicas/venv/lib/python3.12/site-packages/flask/app.py", line 865, in dispatch_request
    return self.ensure_sync(self.view_functions[rule.endpoint])(**view_args)  # type: ignore[no-any-return]
           ^^^^^^^^^^^^^^^^^^^^^^^^^^^^^^^^^^^^^^^^^^^^^^^^^^^^^^^^^^^^^^^^^
  File "/home/user/Desktop/uvlhub_practicas/montaito-hub/app/modules/ai/routes.py", line 70, in chat
    if response_text.startswith('dataset-get'):
       ^^^^^^^^^^^^^^^^^^^^^^^^
AttributeError: 'dict' object has no attribute 'startswith'
2024-12-10 17:15:59,063 - app - ERROR - Internal Server Error: 500 Internal Server Error: The server encountered an internal error and was unable to complete your request. Either the server is overloaded or there is an error in the application.
2024-12-10 17:18:51,607 - app - ERROR - Exception on /chat [POST]
Traceback (most recent call last):
  File "/home/user/Desktop/uvlhub_practicas/venv/lib/python3.12/site-packages/flask/app.py", line 1473, in wsgi_app
    response = self.full_dispatch_request()
               ^^^^^^^^^^^^^^^^^^^^^^^^^^^^
  File "/home/user/Desktop/uvlhub_practicas/venv/lib/python3.12/site-packages/flask/app.py", line 882, in full_dispatch_request
    rv = self.handle_user_exception(e)
         ^^^^^^^^^^^^^^^^^^^^^^^^^^^^^
  File "/home/user/Desktop/uvlhub_practicas/venv/lib/python3.12/site-packages/flask_restful/__init__.py", line 298, in error_router
    return original_handler(e)
           ^^^^^^^^^^^^^^^^^^^
  File "/home/user/Desktop/uvlhub_practicas/venv/lib/python3.12/site-packages/flask/app.py", line 880, in full_dispatch_request
    rv = self.dispatch_request()
         ^^^^^^^^^^^^^^^^^^^^^^^
  File "/home/user/Desktop/uvlhub_practicas/venv/lib/python3.12/site-packages/flask/app.py", line 865, in dispatch_request
    return self.ensure_sync(self.view_functions[rule.endpoint])(**view_args)  # type: ignore[no-any-return]
           ^^^^^^^^^^^^^^^^^^^^^^^^^^^^^^^^^^^^^^^^^^^^^^^^^^^^^^^^^^^^^^^^^
  File "/home/user/Desktop/uvlhub_practicas/montaito-hub/app/modules/ai/routes.py", line 72, in chat
    if response_text.startswith('dataset-get'):
       ^^^^^^^^^^^^^^^^^^^^^^^^
AttributeError: 'dict' object has no attribute 'startswith'
2024-12-10 17:18:51,612 - app - ERROR - Internal Server Error: 500 Internal Server Error: The server encountered an internal error and was unable to complete your request. Either the server is overloaded or there is an error in the application.
2024-12-10 17:18:56,310 - app - ERROR - Exception on /chat [POST]
Traceback (most recent call last):
  File "/home/user/Desktop/uvlhub_practicas/venv/lib/python3.12/site-packages/flask/app.py", line 1473, in wsgi_app
    response = self.full_dispatch_request()
               ^^^^^^^^^^^^^^^^^^^^^^^^^^^^
  File "/home/user/Desktop/uvlhub_practicas/venv/lib/python3.12/site-packages/flask/app.py", line 882, in full_dispatch_request
    rv = self.handle_user_exception(e)
         ^^^^^^^^^^^^^^^^^^^^^^^^^^^^^
  File "/home/user/Desktop/uvlhub_practicas/venv/lib/python3.12/site-packages/flask_restful/__init__.py", line 298, in error_router
    return original_handler(e)
           ^^^^^^^^^^^^^^^^^^^
  File "/home/user/Desktop/uvlhub_practicas/venv/lib/python3.12/site-packages/flask/app.py", line 880, in full_dispatch_request
    rv = self.dispatch_request()
         ^^^^^^^^^^^^^^^^^^^^^^^
  File "/home/user/Desktop/uvlhub_practicas/venv/lib/python3.12/site-packages/flask/app.py", line 865, in dispatch_request
    return self.ensure_sync(self.view_functions[rule.endpoint])(**view_args)  # type: ignore[no-any-return]
           ^^^^^^^^^^^^^^^^^^^^^^^^^^^^^^^^^^^^^^^^^^^^^^^^^^^^^^^^^^^^^^^^^
  File "/home/user/Desktop/uvlhub_practicas/montaito-hub/app/modules/ai/routes.py", line 72, in chat
    if response_text.startswith('dataset-get'):
       ^^^^^^^^^^^^^^^^^^^^^^^^
AttributeError: 'dict' object has no attribute 'startswith'
2024-12-10 17:18:56,311 - app - ERROR - Internal Server Error: 500 Internal Server Error: The server encountered an internal error and was unable to complete your request. Either the server is overloaded or there is an error in the application.
